<?xml version="1.0" ?>
<robot name="turtlebot3_waffle_pi" xmlns:xacro="http://ros.org/wiki/xacro">

  <xacro:arg name="namespace" default=""/>
  <xacro:property name="namespace" value="$(arg namespace)"/>

  <material name="black"><color rgba="0.0 0.0 0.0 1.0"/></material>
  <material name="dark"><color rgba="0.3 0.3 0.3 1.0"/></material>
  <material name="light_black"><color rgba="0.4 0.4 0.4 1.0"/></material>

  <link name="${namespace}base_footprint"/>

  <joint name="${namespace}base_joint" type="fixed">
    <parent link="${namespace}base_footprint"/>
    <child link="${namespace}base_link" />
    <origin xyz="0 0 0.010" rpy="0 0 0"/>
  </joint>

  <link name="${namespace}base_link">
    <visual>
      <origin xyz="-0.064 0 0.0" rpy="0 0 0"/>
      <geometry>
        <mesh filename="package://sim_robot/meshes/bases/waffle_pi_base.stl" scale="0.001 0.001 0.001"/>
      </geometry>
      <material name="light_black"/>
    </visual>
    <collision>
      <origin xyz="-0.064 0 0.047" rpy="0 0 0"/>
      <geometry><box size="0.266 0.266 0.094"/></geometry>
    </collision>
    <inertial>
      <origin xyz="0 0 0" rpy="0 0 0"/>
      <mass value="1.3729096e+00"/>
      <inertia ixx="8.7002718e-03" ixy="-4.7576583e-05" ixz="1.1160499e-04"
               iyy="8.6195418e-03" iyz="-3.5422299e-06" izz="1.4612727e-02" />
    </inertial>
  </link>

  <joint name="${namespace}wheel_left_joint" type="continuous">
    <parent link="${namespace}base_link"/>
    <child link="${namespace}wheel_left_link"/>
    <origin xyz="0.0 0.144 0.023" rpy="-1.57 0 0"/>
    <axis xyz="0 0 1"/>
  </joint>

  <link name="${namespace}wheel_left_link">
    <visual>
      <origin xyz="0 0 0" rpy="1.57 0 0"/>
      <geometry><mesh filename="package://sim_robot/meshes/wheels/left_tire.stl" scale="0.001 0.001 0.001"/></geometry>
      <material name="dark"/>
    </visual>
    <collision>
      <origin xyz="0 0 0" rpy="0 0 0"/>
      <geometry><cylinder length="0.018" radius="0.033"/></geometry>
    </collision>
    <inertial>
      <origin xyz="0 0 0" /><mass value="2.8498940e-02" />
      <inertia ixx="1.1175580e-05" ixy="-4.2369783e-11" ixz="-5.9381719e-09" iyy="1.1192413e-05" iyz="-1.4400107e-11" izz="2.0712558e-05" />
    </inertial>
  </link>

  <joint name="${namespace}wheel_right_joint" type="continuous">
    <parent link="${namespace}base_link"/>
    <child link="${namespace}wheel_right_link"/>
    <origin xyz="0.0 -0.144 0.023" rpy="-1.57 0 0"/>
    <axis xyz="0 0 1"/>
  </joint>

  <link name="${namespace}wheel_right_link">
    <visual>
      <origin xyz="0 0 0" rpy="1.57 0 0"/>
      <geometry><mesh filename="package://sim_robot/meshes/wheels/right_tire.stl" scale="0.001 0.001 0.001"/></geometry>
      <material name="dark"/>
    </visual>
    <collision>
      <origin xyz="0 0 0" rpy="0 0 0"/>
      <geometry><cylinder length="0.018" radius="0.033"/></geometry>
    </collision>
    <inertial>
      <origin xyz="0 0 0" /><mass value="2.8498940e-02" />
      <inertia ixx="1.1175580e-05" ixy="-4.2369783e-11" ixz="-5.9381719e-09" iyy="1.1192413e-05" iyz="-1.4400107e-11" izz="2.0712558e-05" />
    </inertial>
  </link>

  <joint name="${namespace}caster_back_right_joint" type="fixed">
    <parent link="${namespace}base_link"/>
    <child link="${namespace}caster_back_right_link"/>
    <origin xyz="-0.177 -0.064 -0.004" rpy="-1.57 0 0"/>
  </joint>
  <link name="${namespace}caster_back_right_link">
    <collision><geometry><box size="0.030 0.009 0.020"/></geometry></collision>
    <inertial><mass value="0.005" /><inertia ixx="0.0001" ixy="0.0" ixz="0.0" iyy="0.0001" iyz="0.0" izz="0.0001" /></inertial>
  </link>

  <joint name="${namespace}caster_back_left_joint" type="fixed">
    <parent link="${namespace}base_link"/>
    <child link="${namespace}caster_back_left_link"/>
    <origin xyz="-0.177 0.064 -0.004" rpy="-1.57 0 0"/>
  </joint>
  <link name="${namespace}caster_back_left_link">
    <collision><geometry><box size="0.030 0.009 0.020"/></geometry></collision>
    <inertial><mass value="0.005" /><inertia ixx="0.0001" ixy="0.0" ixz="0.0" iyy="0.0001" iyz="0.0" izz="0.0001" /></inertial>
  </link>

  <joint name="${namespace}imu_joint" type="fixed">
    <parent link="${namespace}base_link"/>
    <child link="${namespace}imu_link"/>
    <origin xyz="0.0 0 0.068" rpy="0 0 0"/>
  </joint>
  <link name="${namespace}imu_link"/>

  <joint name="${namespace}scan_joint" type="fixed">
    <parent link="${namespace}base_link"/>
    <child link="${namespace}base_scan"/>
    <origin xyz="-0.064 0 0.122" rpy="0 0 0"/>
  </joint>
  <link name="${namespace}base_scan">
    <visual>
      <origin xyz="0 0 0.0" rpy="0 0 0"/>
      <geometry><mesh filename="package://sim_robot/meshes/sensors/lds.stl" scale="0.001 0.001 0.001"/></geometry>
      <material name="dark"/>
    </visual>
    <collision>
      <origin xyz="0.015 0 -0.0065" rpy="0 0 0"/>
      <geometry><cylinder length="0.0315" radius="0.055"/></geometry>
    </collision>
    <inertial><mass value="0.114" /><inertia ixx="0.001" ixy="0.0" ixz="0.0" iyy="0.001" iyz="0.0" izz="0.001" /></inertial>
  </link>

  <joint name="${namespace}camera_joint" type="fixed">
    <origin xyz="0.073 0 0.084" rpy="0 0 0"/>
    <parent link="${namespace}base_link"/>
    <child link="${namespace}camera_link"/>
  </joint>
  <link name="${namespace}camera_link">
    <visual>
      <origin xyz="0.005 0 0" rpy="0 0 0"/>
      <geometry><box size="0.008 0.01 0.020"/></geometry>
    </visual>
    <collision>
      <origin xyz="0.005 0 0" rpy="0 0 0"/>
      <geometry><box size="0.008 0.01 0.020"/></geometry>
    </collision>
  </link>

  <joint name="${namespace}camera_rgb_joint" type="fixed">
    <origin xyz="0.003 0.011 0.009" rpy="0 0 0"/>
    <parent link="${namespace}camera_link"/>
    <child link="${namespace}camera_rgb_frame"/>
  </joint>
  <link name="${namespace}camera_rgb_frame"/>

  <joint name="${namespace}camera_rgb_optical_joint" type="fixed">
    <origin xyz="0 0 0" rpy="-1.57 0 -1.57"/>
    <parent link="${namespace}camera_rgb_frame"/>
    <child link="${namespace}camera_rgb_optical_frame"/>
  </joint>
  <link name="${namespace}camera_rgb_optical_frame"/>

  <gazebo reference="${namespace}base_link"><material>Gazebo/DarkGrey</material></gazebo>
  <gazebo reference="${namespace}wheel_left_link"><mu1>0.1</mu1><mu2>0.1</mu2><kp>500000.0</kp><kd>10.0</kd><material>Gazebo/FlatBlack</material></gazebo>
  <gazebo reference="${namespace}wheel_right_link"><mu1>0.1</mu1><mu2>0.1</mu2><kp>500000.0</kp><kd>10.0</kd><material>Gazebo/FlatBlack</material></gazebo>
  <gazebo reference="${namespace}caster_back_right_link"><mu1>0.01</mu1><mu2>0.01</mu2><material>Gazebo/FlatBlack</material></gazebo>
  <gazebo reference="${namespace}caster_back_left_link"><mu1>0.01</mu1><mu2>0.01</mu2><material>Gazebo/FlatBlack</material></gazebo>

  <gazebo>
    <plugin name="turtlebot3_waffle_pi_controller" filename="libgazebo_ros_diff_drive.so">
      <ros><namespace>${namespace}</namespace></ros>
      <update_rate>30</update_rate>
      <left_joint>${namespace}wheel_left_joint</left_joint>
      <right_joint>${namespace}wheel_right_joint</right_joint>
      <wheel_separation>0.287</wheel_separation>
      <wheel_diameter>0.066</wheel_diameter>
      <max_wheel_torque>20</max_wheel_torque>
      <max_wheel_acceleration>1.0</max_wheel_acceleration>
      <command_topic>cmd_vel</command_topic>
      <publish_odom>true</publish_odom>
      <publish_odom_tf>true</publish_odom_tf>
      <publish_wheel_tf>false</publish_wheel_tf> 
      <odometry_topic>odom</odometry_topic>
      <odometry_frame>${namespace}odom</odometry_frame>
      <robot_base_frame>${namespace}base_footprint</robot_base_frame>
    </plugin>
  </gazebo>

  <gazebo>
    <plugin name="turtlebot3_joint_state" filename="libgazebo_ros_joint_state_publisher.so">
      <ros><remapping>~/out:=joint_states</remapping></ros>
      <update_rate>30</update_rate>
      <joint_name>${namespace}wheel_left_joint</joint_name>
      <joint_name>${namespace}wheel_right_joint</joint_name>
    </plugin>
  </gazebo>

  <gazebo reference="${namespace}imu_link">
    <sensor name="imu" type="imu">
      <always_on>true</always_on>
      <update_rate>200</update_rate>
      <plugin name="turtlebot3_imu_controller" filename="libgazebo_ros_imu_sensor.so">
        <ros><remapping>~/out:=imu</remapping></ros>
      </plugin>
    </sensor>
  </gazebo>

  <gazebo reference="${namespace}base_scan">
    <sensor name="lds_lfcd_sensor" type="ray">
      <pose>0 0 0 0 0 0</pose>
      <always_on>true</always_on>
      <update_rate>5</update_rate>
      <visualize>false</visualize>
      <ray>
        <scan>
          <horizontal>
            <samples>360</samples>
            <resolution>1</resolution>
            <min_angle>0.0</min_angle>
            <max_angle>6.28319</max_angle>
          </horizontal>
        </scan>
        <range>
          <min>0.120</min>
          <max>3.5</max>
          <resolution>0.015</resolution>
        </range>
      </ray>
      <plugin name="turtlebot3_laserscan_controller" filename="libgazebo_ros_ray_sensor.so">
        <ros><remapping>~/out:=scan</remapping></ros>
        <output_type>sensor_msgs/LaserScan</output_type>
        <frame_name>${namespace}base_scan</frame_name>
      </plugin>
    </sensor>
  </gazebo>

  <gazebo reference="${namespace}camera_rgb_frame">
    <sensor name="camera" type="camera">
      <always_on>true</always_on>
      <update_rate>30</update_rate>
      <visualize>false</visualize>
      <camera>
        <horizontal_fov>1.085595</horizontal_fov>
        <image><width>640</width><height>480</height><format>R8G8B8</format></image>
        <clip><near>0.03</near><far>100</far></clip>
      </camera>
      <plugin name="camera_controller" filename="libgazebo_ros_camera.so">
        <ros>
          <remapping>~/image_raw:=image_raw</remapping>
          <remapping>~/camera_info:=camera_info</remapping>
        </ros>
        <frame_name>${namespace}camera_rgb_optical_frame</frame_name>
      </plugin>
    </sensor>
  </gazebo>

</robot>